<?xml version="1.0" ?>
<robot name="caddybot" xmlns:xacro="http://ros.org/wiki/xacro">
  <xacro:include filename="$(find turtlebot3_description)/urdf/common_properties.xacro"/>
  <xacro:include filename="$(find caddybot_urdf)/urdf/caddyboturdf.gazebo.xacro"/> 
  
  <link name="base_footprint"/>

  <joint name="base_joint" type="fixed">
    <parent link="base_footprint"/>
    <child link="base_link"/>
    <origin xyz="0.0 0.0 0.3" rpy="0 0.0 3.14159265359"/>
  </joint>
<link name="imu_link"/>

  <joint name="imu_joint" type="fixed">
    <parent link="base_link"/>
    <child link="imu_link"/>
    <origin xyz="-0.1625 0.0 0.13" rpy="0 0 3.141592"/>
  </joint>

   <link name="unilidar_lidar"/>

  <joint name="unilidar_joint" type="fixed">
    <parent link="base_link"/>
    <child link="unilidar_lidar"/>
    <origin xyz="-0.36 0.0 0.15" rpy="0 1.50970980298 3.141592"/>
  </joint>  
   <link name="cam_link"/>

  <joint name="cam_joint" type="fixed">
    <parent link="base_link"/>
    <child link="cam_link"/>
     <origin xyz="-0.31 0.0 0.20" rpy="0 0 3.141592"/>
  </joint>
  
  <xacro:include filename="$(find realsense2_description)/urdf/_d435.gazebo.xacro"/>
  <xacro:gazebo_d435 camera_name="camera" reference_link="cam_link" topics_ns="camera"
  depth_optical_frame="camera_depth_optical_frame" color_optical_frame="camera_color_optical_frame"
  infrared1_optical_frame="camera_infrared1_optical_frame" infrared2_optical_frame="camera_infrared2_optical_frame"
  publish_pointcloud="true"/>  
  <link
    name="base_link">
    <inertial>
      <origin
        xyz="0.13001 0.0030047 0.020182"
        rpy="0 0 0" />
      <mass
        value="23.189" />
      <inertia
        ixx="0.1628"
        ixy="3.4324E-05"
        ixz="-0.0063706"
        iyy="0.21523"
        iyz="-5.4253E-05"
        izz="0.22576" />
    </inertial>
    <visual>
      <origin
        xyz="0.25 0 0.1"
        rpy="0 0 0" />
      <geometry>
        <box size="1 0.5 0.5" />
      </geometry>
      <material
        name="">
        <color
          rgba="0.792156862745098 0.819607843137255 0.933333333333333 1" />
      </material>
    </visual>
    <collision>
      <origin
        xyz="0.25 0 0.1"
        rpy="0 0 0" />
      <geometry>
        <box size="1 0.5 0.5" />
      </geometry>
    </collision>
  </link>
  
  <link
    name="LeftF_Link">
    <inertial>
      <origin
        xyz="3.5645E-09 2.0638E-08 0.02868"
        rpy="0 0 0" />
      <mass
        value="3.1488" />
      <inertia
        ixx="0.036853"
        ixy="-7.098E-10"
        ixz="-9.4404E-10"
        iyy="0.036853"
        iyz="5.3754E-10"
        izz="0.059899" />
    </inertial>
    <visual>
      <origin
        xyz="0 0 0"
        rpy="0 0 0" /><!--
      <geometry>
        <mesh
          filename="package://caddybot_urdf/meshes/LeftF_Link.STL" />
      </geometry>-->
      <geometry>
        <cylinder radius="0.18" length="0.15"/>
      </geometry> 
      <material
        name="">
        <color
          rgba="0.75294 0.75294 0.75294 1" />
      </material>
    </visual>
    <collision>
      <origin
        xyz="0 0 0"
        rpy="0 0 0" /><!--
      <geometry>
        <mesh
          filename="package://caddybot_urdf/meshes/LeftF_Link.STL" />
      </geometry>-->
      <geometry>
        <cylinder radius="0.18" length="0.15"/>
      </geometry> 
    </collision>
  </link>
  <joint
    name="LeftFlink"
    type="continuous">
    <origin
      xyz="-0.1625 -0.47151 -0.15967"
      rpy="1.5708 0 3.141592" />
    <parent
      link="base_link" />
    <child
      link="LeftF_Link" />
    <axis
      xyz="0 0 -1" />
  </joint>
  <link
    name="RightF_Link">
    <inertial>
      <origin
        xyz="5.47624412483572E-09 -4.71908490409789E-09 -0.0286797314543985"
        rpy="0 0 0" />
      <mass
        value="3.1488296265046" />
      <inertia
        ixx="0.036853305692685"
        ixy="5.45140823185881E-10"
        ixz="-1.69602894516381E-09"
        iyy="0.0368533056763454"
        iyz="-9.32672289049548E-10"
        izz="0.0598990431182657" />
    </inertial>
    <visual>
      <origin
        xyz="0 0 0"
        rpy="0 0 0" /><!--
      <geometry>
        <mesh
          filename="package://caddybot_urdf/meshes/RightF_Link.STL" />
      </geometry>-->
      <geometry>
        <cylinder radius="0.18" length="0.15"/>
      </geometry> 
      <material
        name="">
        <color
          rgba="0.752941176470588 0.752941176470588 0.752941176470588 1" />
      </material>
    </visual>
    <collision>
      <origin
        xyz="0 0 0"
        rpy="0 0 0" /><!--
      <geometry>
        <mesh
          filename="package://caddybot_urdf/meshes/RightF_Link.STL" />
      </geometry>-->
      <geometry>
        <cylinder radius="0.18" length="0.15"/>
      </geometry> 
    </collision>
  </link>
  <joint
    name="RightFlink"
    type="continuous">
    <origin
      xyz="-0.1625 0.47151 -0.15967"
      rpy="1.5708 0 3.141592" />
    <parent
      link="base_link" />
    <child
      link="RightF_Link" />
    <axis
      xyz="0 0 -1" />
  </joint>
  <link
    name="LB_Link">
    <inertial>
      <origin
        xyz="0 -1.38777878078145E-17 0"
        rpy="0 0 0" />
      <mass
        value="0.672889345058735" />
      <inertia
        ixx="0.00102415281934837"
        ixy="-9.64236297623981E-50"
        ixz="9.32002799941477E-19"
        iyy="0.00102415281934837"
        iyz="-3.93279156307764E-35"
        izz="0.00188210863417053" />
    </inertial>
    <visual>
      <origin
        xyz="0 0 0"
        rpy="0 0 0" />
      <geometry>
        <mesh
          filename="package://caddybot_urdf/meshes/LB_Link.STL" />
      </geometry>
      <material
        name="">
        <color
          rgba="0.792156862745098 0.819607843137255 0.933333333333333 1" />
      </material>
    </visual>
    <collision>
      <origin
        xyz="0 0 0"
        rpy="0 0 0" />
      <geometry>
        <mesh
          filename="package://caddybot_urdf/meshes/LB_Link.STL" />
      </geometry>
    </collision>
  </link>
   

  <joint
    name="casterLlink"
    type="continuous">
    <origin
      xyz="0.71 -0.35316 -0.179"
      rpy="0 0 0" />
    <parent
      link="base_link" />
    <child
      link="casterL_Link" />
    <axis
      xyz="0 0 1" />
  </joint>
   
  <link
    name="casterL_Link">
      <origin
        xyz="0 0 0"
        rpy="0 0 0" />
    <inertial>
      <origin
        xyz="0 0 0"
        rpy="0 0 0" />
      <mass
        value="0.31488296265046" />
      <inertia
        ixx="0.036853305692685"
        ixy="0.45140823185881E-10"
        ixz="0.69602894516381E-09"
        iyy="0.0368533056763454"
        iyz="0.32672289049548E-10"
        izz="0.0598990431182657" />
    </inertial>    
    <visual>
      <origin
        xyz="0 0 0"
        rpy="0 0 0" />
      <geometry>
        <box size= "0.05 0.05 0.05" />
      </geometry>
    </visual>
  </link>
 

  <joint
    name="LBlink"
    type="continuous">
    <origin
      xyz="0.088 0 -0.12"
      rpy="-1.5708 0 0" />
    <parent
      link="casterL_Link" />
    <child
      link="LB_Link" />
    <axis
      xyz="0 0 -1" />
  </joint>

  <joint
    name="casterRlink"
    type="continuous">
    <origin
      xyz="0.71 0.35316 -0.179"
      rpy="0 0 0" />
    <parent
      link="base_link" />
    <child
      link="casterR_Link" />
    <axis
      xyz="0 0 1" />
  </joint>
   
  <link
    name="casterR_Link">
      <origin
        xyz="0 0 0"
        rpy="0 0 0" />
    <inertial>
      <origin
        xyz="0 0 0"
        rpy="0 0 0" />
      <mass
        value="0.31488296265046" />
      <inertia
        ixx="0.036853305692685"
        ixy="0.45140823185881E-10"
        ixz="0.69602894516381E-09"
        iyy="0.0368533056763454"
        iyz="0.32672289049548E-10"
        izz="0.0598990431182657" />
    </inertial>
    <visual>
      <origin
        xyz="0 0 0"
        rpy="0 0 0" />
      <geometry>
        <box size= "0.05 0.05 0.05" />
      </geometry>
    </visual>
  </link>
     
  <link
    name="RB_Link">
    <inertial>
      <origin
        xyz="0 -1.38777878078145E-17 0"
        rpy="0 0 0" />
      <mass
        value="0.672889345058735" />
      <inertia
        ixx="0.00102415281934837"
        ixy="1.70075227112675E-20"
        ixz="-1.96517608339373E-18"
        iyy="0.00102415281934837"
        iyz="-5.32937046757169E-21"
        izz="0.00188210863417053" />
    </inertial>
    <visual>
      <origin
        xyz="0 0 0"
        rpy="0 0 0" />
      <geometry>
        <mesh
          filename="package://caddybot_urdf/meshes/RB_Link.STL" />
      </geometry>
      <material
        name="">
        <color
          rgba="0.792156862745098 0.819607843137255 0.933333333333333 1" />
      </material>
    </visual>
    <collision>
      <origin
        xyz="0 0 0"
        rpy="0 0 0" />
      <geometry>
        <mesh
          filename="package://caddybot_urdf/meshes/RB_Link.STL" />
      </geometry>
    </collision>
  </link>
  <joint
    name="RBlink"
    type="continuous">
    <origin
      xyz="0.088 0 -0.12"
      rpy="-1.5708 0 0" />
    <parent
      link="casterR_Link" />
    <child
      link="RB_Link" />
    <axis
      xyz="0 0 -1" />
  </joint>

</robot>


