<?xml version="1.0" ?>
<!-- =================================================================================== -->
<!-- |    This document was autogenerated by xacro from caddyboturdf.xacro             | -->
<!-- |    EDITING THIS FILE BY HAND IS NOT RECOMMENDED                                 | -->
<!-- =================================================================================== -->
<robot name="caddybot">
  <!-- Init colour -->
  <material name="black">
    <color rgba="0.0 0.0 0.0 1.0"/>
  </material>
  <material name="dark">
    <color rgba="0.3 0.3 0.3 1.0"/>
  </material>
  <material name="light_black">
    <color rgba="0.4 0.4 0.4 1.0"/>
  </material>
  <material name="blue">
    <color rgba="0.0 0.0 0.8 1.0"/>
  </material>
  <material name="green">
    <color rgba="0.0 0.8 0.0 1.0"/>
  </material>
  <material name="grey">
    <color rgba="0.5 0.5 0.5 1.0"/>
  </material>
  <material name="orange">
    <color rgba="1.0 0.4235294117647059 0.0392156862745098 1.0"/>
  </material>
  <material name="brown">
    <color rgba="0.8705882352941177 0.8117647058823529 0.7647058823529411 1.0"/>
  </material>
  <material name="red">
    <color rgba="0.8 0.0 0.0 1.0"/>
  </material>
  <material name="white">
    <color rgba="1.0 1.0 1.0 1.0"/>
  </material>
  <gazebo reference="base_link">
    <material>Gazebo/Grey</material>
  </gazebo>
  <gazebo reference="LeftF_Link">
    <mu1>1</mu1>
    <mu2>0.7</mu2>
    <kp>500000.0</kp>
    <kd>10.0</kd>
    <minDepth>0.001</minDepth>
    <maxVel>0.22</maxVel>
    <fdir1>1 0 0</fdir1>
    <material>Gazebo/Blue</material>
  </gazebo>
  <gazebo reference="RightF_Link">
    <mu1>1</mu1>
    <mu2>0.7</mu2>
    <kp>500000.0</kp>
    <kd>10.0</kd>
    <minDepth>0.001</minDepth>
    <maxVel>0.22</maxVel>
    <fdir1>1 0 0</fdir1>
    <material>Gazebo/Blue</material>
  </gazebo>
  <gazebo reference="LB_Link">
    <mu1>0.8</mu1>
    <mu2>0.5</mu2>
    <kp>500000.0</kp>
    <kd>10.0</kd>
    <minDepth>0.001</minDepth>
    <maxVel>0.22</maxVel>
    <fdir1>1 0 0</fdir1>
    <material>Gazebo/Red</material>
  </gazebo>
  <gazebo reference="casterL_Link">
    <mu1>0.8</mu1>
    <mu2>0.5</mu2>
    <material>Gazebo/Red</material>
  </gazebo>
  <gazebo reference="casterR_Link">
    <mu1>0.8</mu1>
    <mu2>0.5</mu2>
    <material>Gazebo/Red</material>
  </gazebo>
  <gazebo reference="RB_Link">
    <mu1>0.8</mu1>
    <mu2>0.5</mu2>
    <kp>500000.0</kp>
    <kd>10.0</kd>
    <minDepth>0.001</minDepth>
    <maxVel>0.22</maxVel>
    <fdir1>1 0 0</fdir1>
    <material>Gazebo/Red</material>
  </gazebo>
  <gazebo>
    <plugin filename="libgazebo_ros_diff_drive.so" name="caddy_controller">
      <commandTopic>cmd_vel</commandTopic>
      <odometryTopic>odom</odometryTopic>
      <odometryFrame>odom</odometryFrame>
      <odometrySource>world</odometrySource>
      <publishOdomTF>true</publishOdomTF>
      <robotBaseFrame>base_footprint</robotBaseFrame>
      <publishWheelTF>false</publishWheelTF>
      <publishTf>true</publishTf>
      <publishWheelJointState>true</publishWheelJointState>
      <legacyMode>false</legacyMode>
      <updateRate>50</updateRate>
      <leftJoint>LeftFlink</leftJoint>
      <rightJoint>RightFlink</rightJoint>
      <wheelSeparation>0.94301</wheelSeparation>
      <wheelDiameter>0.310</wheelDiameter>
      <wheelAcceleration>10.0</wheelAcceleration>
      <wheelTorque>20</wheelTorque>
      <rosDebugLevel>debug</rosDebugLevel>
    </plugin>
  </gazebo>
  <gazebo reference="imu_link">
    <sensor name="imu" type="imu">
      <always_on>true</always_on>
      <visualize>false</visualize>
    </sensor>
  </gazebo>
  <link name="unilidar_lidar"/>
  
  <joint name="unilidar_joint" type="fixed">
    <parent link="base_link"/>
    <child link="unilidar_lidar"/>
    <origin xyz="-0.36 0.0 0.15" rpy="0 1.50970980298 3.141592"/>
  </joint>  

  <gazebo reference="cam_link">
    <sensor type="ray" name="lds_lfcd_sensor">
      <pose>0 0 0 0 0 0</pose>
      <visualize>true</visualize>
      <update_rate>10</update_rate>
      <ray>
        <scan>
          <horizontal>
            <samples>40</samples>
            <resolution>1</resolution>
            <min_angle>-1.5708</min_angle>
            <max_angle>1.5708</max_angle>
          </horizontal>
          <vertical>
            <samples>40</samples>
            <resolution>1</resolution>
            <min_angle>0</min_angle>
            <max_angle>-1.5708</max_angle>
          </vertical>
        </scan>
        <range>
          <min>0.50</min>
          <max>30</max>
          <resolution>0.015</resolution>
        </range>
        <noise>
          <type>gaussian</type>
          <mean>0.0</mean>
          <stddev>0.01</stddev>
        </noise>
      </ray>
      <plugin name="gazebo_ros_lds_lfcd_controller" filename="libgazebo_ros_laser.so">
        <topicName>lidar_scan</topicName>
        <frameName>base_footprint</frameName>
      </plugin>
    </sensor>
  </gazebo>

  <gazebo>
    <plugin filename="libgazebo_ros_imu.so" name="imu_plugin">
      <alwaysOn>true</alwaysOn>
      <bodyName>imu_link</bodyName>
      <frameName>imu_link</frameName>
      <topicName>imu</topicName>
      <serviceName>imu_service</serviceName>
      <gaussianNoise>0.0</gaussianNoise>
      <updateRate>50</updateRate>
      <imu>
        <noise>
          <type>gaussian</type>
          <rate>
            <mean>0.0</mean>
            <stddev>2e-4</stddev>
            <bias_mean>0.0000075</bias_mean>
            <bias_stddev>0.0000008</bias_stddev>
          </rate>
          <accel>
            <mean>0.0</mean>
            <stddev>1.7e-2</stddev>
            <bias_mean>0.1</bias_mean>
            <bias_stddev>0.001</bias_stddev>
          </accel>
        </noise>
      </imu>
    </plugin>
  </gazebo>
  <link name="base_footprint"/>
  <joint name="base_joint" type="fixed">
    <parent link="base_footprint"/>
    <child link="base_link"/>
    <origin rpy="0 -0.06 3.14159265359" xyz="0.0 0.0 0.30"/>
  </joint>
  <link name="imu_link"/>
  <joint name="imu_joint" type="fixed">
    <parent link="base_link"/>
    <child link="imu_link"/>
    <origin rpy="0 0 3.141592" xyz="-0.1 0.0 0"/>
  </joint>  
  <link name="cam_link"/>
  <joint name="cam_joint" type="fixed">
    <parent link="base_link"/>
    <child link="cam_link"/>
    <origin rpy="0 0 3.141592" xyz="-0.3 0.0 0.18"/>
  </joint>
  <gazebo reference="cam_link">
    <self_collide>0</self_collide>
    <enable_wind>0</enable_wind>
    <kinematic>0</kinematic>
    <gravity>1</gravity>
    <!--<mu>1</mu>-->
    <mu2>1</mu2>
    <fdir1>0 0 0</fdir1>
    <!--<slip1>0</slip1>
      <slip2>0</slip2>-->
    <kp>1e+13</kp>
    <kd>1</kd>
    <!--<max_vel>0.01</max_vel>
      <min_depth>0</min_depth>-->
    <sensor name="cameracolor" type="camera">
      <camera name="camera">
        <horizontal_fov>1.2112585008840648</horizontal_fov>
        <image>
          <width>640</width>
          <height>480</height>
          <format>RGB_INT8</format>
        </image>
        <clip>
          <near>0.1</near>
          <far>100</far>
        </clip>
        <noise>
          <type>gaussian</type>
          <mean>0.0</mean>
          <stddev>0.007</stddev>
        </noise>
      </camera>
      <always_on>1</always_on>
      <update_rate>30</update_rate>
      <visualize>1</visualize>
    </sensor>
    <sensor name="cameraired1" type="camera">
      <camera name="camera">
        <horizontal_fov>1.4870205226991688</horizontal_fov>
        <image>
          <width>1280</width>
          <height>720</height>
          <format>L_INT8</format>
        </image>
        <clip>
          <near>0.1</near>
          <far>100</far>
        </clip>
        <noise>
          <type>gaussian</type>
          <mean>0.0</mean>
          <stddev>0.05</stddev>
        </noise>
      </camera>
      <always_on>1</always_on>
      <update_rate>90</update_rate>
      <visualize>0</visualize>
    </sensor>
    <sensor name="cameraired2" type="camera">
      <camera name="camera">
        <horizontal_fov>1.4870205226991688</horizontal_fov>
        <image>
          <width>1280</width>
          <height>720</height>
          <format>L_INT8</format>
        </image>
        <clip>
          <near>0.1</near>
          <far>100</far>
        </clip>
        <noise>
          <type>gaussian</type>
          <mean>0.0</mean>
          <stddev>0.05</stddev>
        </noise>
      </camera>
      <always_on>1</always_on>
      <update_rate>90</update_rate>
      <visualize>0</visualize>
    </sensor>
    <sensor name="cameradepth" type="depth">
      <camera name="camera">
        <horizontal_fov>1.4870205226991688</horizontal_fov>
        <image>
          <width>640</width>
          <height>480</height>
        </image>
        <clip>
          <near>0.1</near>
          <far>100</far>
        </clip>
        <noise>
          <type>gaussian</type>
          <mean>0.0</mean>
          <stddev>0.100</stddev>
        </noise>
      </camera>
      <always_on>1</always_on>
      <update_rate>90</update_rate>
      <visualize>0</visualize>
    </sensor>
  </gazebo>
  <gazebo>
    <plugin filename="librealsense_gazebo_plugin.so" name="camera">
      <prefix>camera</prefix>
      <depthUpdateRate>30.0</depthUpdateRate>
      <colorUpdateRate>30.0</colorUpdateRate>
      <infraredUpdateRate>30.0</infraredUpdateRate>
      <depthTopicName>depth/image_raw</depthTopicName>
      <depthCameraInfoTopicName>depth/camera_info</depthCameraInfoTopicName>
      <colorTopicName>color/image_raw</colorTopicName>
      <colorCameraInfoTopicName>color/camera_info</colorCameraInfoTopicName>
      <infrared1TopicName>infra1/image_raw</infrared1TopicName>
      <infrared1CameraInfoTopicName>infra1/camera_info</infrared1CameraInfoTopicName>
      <infrared2TopicName>infra2/image_raw</infrared2TopicName>
      <infrared2CameraInfoTopicName>infra2/camera_info</infrared2CameraInfoTopicName>
      <colorOpticalframeName>camera_color_optical_frame</colorOpticalframeName>
      <depthOpticalframeName>camera_depth_optical_frame</depthOpticalframeName>
      <infrared1OpticalframeName>camera_infrared1_optical_frame</infrared1OpticalframeName>
      <infrared2OpticalframeName>camera_infrared2_optical_frame</infrared2OpticalframeName>
      <rangeMinDepth>0.2</rangeMinDepth>
      <rangeMaxDepth>10.0</rangeMaxDepth>
      <pointCloud>True</pointCloud>
      <pointCloudTopicName>depth/color/points</pointCloudTopicName>
      <pointCloudCutoff>0.25</pointCloudCutoff>
      <pointCloudCutoffMax>9.0</pointCloudCutoffMax>
    </plugin>
  </gazebo>
  <link name="base_link">
    <inertial>
      <origin rpy="0 0 0" xyz="0.13001 0.0030047 0.020182"/>
      <mass value="23.189"/>
      <inertia ixx="0.1628" ixy="3.4324E-05" ixz="-0.0063706" iyy="0.21523" iyz="-5.4253E-05" izz="0.22576"/>
    </inertial>
    <visual>
      <origin rpy="0 0 0" xyz="0 0 0"/>
      <geometry>
        <mesh filename="package://caddybot_urdf/meshes/base_link.STL"/>
      </geometry>
      <material name="">
        <color rgba="0.792156862745098 0.819607843137255 0.933333333333333 1"/>
      </material>
    </visual>
    <collision>
      <origin rpy="0 0 0" xyz="0 0 0"/>
      <geometry>
        <mesh filename="package://caddybot_urdf/meshes/base_link.STL"/>
      </geometry>
    </collision>
  </link>
  <link name="LeftF_Link">
    <inertial>
      <origin rpy="0 0 0" xyz="3.5645E-09 2.0638E-08 0.02868"/>
      <mass value="3.1488"/>
      <inertia ixx="0.036853" ixy="-7.098E-10" ixz="-9.4404E-10" iyy="0.036853" iyz="5.3754E-10" izz="0.059899"/>
    </inertial>
    <visual>
      <origin rpy="0 0 0" xyz="0 0 0"/>
      <geometry>
        <mesh filename="package://caddybot_urdf/meshes/LeftF_Link.STL"/>
      </geometry>
      <material name="">
        <color rgba="0.75294 0.75294 0.75294 1"/>
      </material>
    </visual>
    <collision>
      <origin rpy="0 0 0" xyz="0 0 0"/>
      <geometry>
        <mesh filename="package://caddybot_urdf/meshes/LeftF_Link.STL"/>
      </geometry>
    </collision>
  </link>
  <joint name="LeftFlink" type="continuous">
    <origin rpy="-1.5708 0 0" xyz="-0.1625 -0.47151 -0.15967"/>
    <parent link="base_link"/>
    <child link="LeftF_Link"/>
    <axis xyz="0 0 -1"/>
  </joint>
  <link name="RightF_Link">
    <inertial>
      <origin rpy="0 0 0" xyz="5.47624412483572E-09 -4.71908490409789E-09 -0.0286797314543985"/>
      <mass value="3.1488296265046"/>
      <inertia ixx="0.036853305692685" ixy="5.45140823185881E-10" ixz="-1.69602894516381E-09" iyy="0.0368533056763454" iyz="-9.32672289049548E-10" izz="0.0598990431182657"/>
    </inertial>
    <visual>
      <origin rpy="0 0 0" xyz="0 0 0"/>
      <geometry>
        <mesh filename="package://caddybot_urdf/meshes/RightF_Link.STL"/>
      </geometry>
      <material name="">
        <color rgba="0.752941176470588 0.752941176470588 0.752941176470588 1"/>
      </material>
    </visual>
    <collision>
      <origin rpy="0 0 0" xyz="0 0 0"/>
      <geometry>
        <mesh filename="package://caddybot_urdf/meshes/RightF_Link.STL"/>
      </geometry>
    </collision>
  </link>
  <joint name="RightFlink" type="continuous">
    <origin rpy="-1.5708 0 0" xyz="-0.1625 0.47151 -0.15967"/>
    <parent link="base_link"/>
    <child link="RightF_Link"/>
    <axis xyz="0 0 -1"/>
  </joint>
  <link name="LB_Link">
    <inertial>
      <origin rpy="0 0 0" xyz="0 -1.38777878078145E-17 0"/>
      <mass value="0.672889345058735"/>
      <inertia ixx="0.00102415281934837" ixy="-9.64236297623981E-50" ixz="9.32002799941477E-19" iyy="0.00102415281934837" iyz="-3.93279156307764E-35" izz="0.00188210863417053"/>
    </inertial>
    <visual>
      <origin rpy="0 0 0" xyz="0 0 0"/>
      <geometry>
        <mesh filename="package://caddybot_urdf/meshes/LB_Link.STL"/>
      </geometry>
      <material name="">
        <color rgba="0.792156862745098 0.819607843137255 0.933333333333333 1"/>
      </material>
    </visual>
    <collision>
      <origin rpy="0 0 0" xyz="0 0 0"/>
      <geometry>
        <mesh filename="package://caddybot_urdf/meshes/LB_Link.STL"/>
      </geometry>
    </collision>
  </link>
  <joint name="casterLlink" type="continuous">
    <origin rpy="0 0 0" xyz="0.71 -0.35316 -0.179"/>
    <parent link="base_link"/>
    <child link="casterL_Link"/>
    <axis xyz="0 0 1"/>
  </joint>
  <link name="casterL_Link">
    <origin rpy="0 0 0" xyz="0 0 0"/>
    <inertial>
      <origin rpy="0 0 0" xyz="0 0 0"/>
      <mass value="0.31488296265046"/>
      <inertia ixx="0.036853305692685" ixy="0.45140823185881E-10" ixz="0.69602894516381E-09" iyy="0.0368533056763454" iyz="0.32672289049548E-10" izz="0.0598990431182657"/>
    </inertial>
    <visual>
      <origin rpy="0 0 0" xyz="0 0 0"/>
      <geometry>
        <box size="0.05 0.05 0.05"/>
      </geometry>
    </visual>
  </link>
  <joint name="LBlink" type="continuous">
    <origin rpy="-1.5708 0 0" xyz="0.088 0 -0.12"/>
    <parent link="casterL_Link"/>
    <child link="LB_Link"/>
    <axis xyz="0 0 -1"/>
  </joint>
  <joint name="casterRlink" type="continuous">
    <origin rpy="0 0 0" xyz="0.71 0.35316 -0.179"/>
    <parent link="base_link"/>
    <child link="casterR_Link"/>
    <axis xyz="0 0 1"/>
  </joint>
  <link name="casterR_Link">
    <origin rpy="0 0 0" xyz="0 0 0"/>
    <inertial>
      <origin rpy="0 0 0" xyz="0 0 0"/>
      <mass value="0.31488296265046"/>
      <inertia ixx="0.036853305692685" ixy="0.45140823185881E-10" ixz="0.69602894516381E-09" iyy="0.0368533056763454" iyz="0.32672289049548E-10" izz="0.0598990431182657"/>
    </inertial>
    <visual>
      <origin rpy="0 0 0" xyz="0 0 0"/>
      <geometry>
        <box size="0.05 0.05 0.05"/>
      </geometry>
    </visual>
  </link>
  <link name="RB_Link">
    <inertial>
      <origin rpy="0 0 0" xyz="0 -1.38777878078145E-17 0"/>
      <mass value="0.672889345058735"/>
      <inertia ixx="0.00102415281934837" ixy="1.70075227112675E-20" ixz="-1.96517608339373E-18" iyy="0.00102415281934837" iyz="-5.32937046757169E-21" izz="0.00188210863417053"/>
    </inertial>
    <visual>
      <origin rpy="0 0 0" xyz="0 0 0"/>
      <geometry>
        <mesh filename="package://caddybot_urdf/meshes/RB_Link.STL"/>
      </geometry>
      <material name="">
        <color rgba="0.792156862745098 0.819607843137255 0.933333333333333 1"/>
      </material>
    </visual>
    <collision>
      <origin rpy="0 0 0" xyz="0 0 0"/>
      <geometry>
        <mesh filename="package://caddybot_urdf/meshes/RB_Link.STL"/>
      </geometry>
    </collision>
  </link>
  <joint name="RBlink" type="continuous">
    <origin rpy="-1.5708 0 0" xyz="0.088 0 -0.12"/>
    <parent link="casterR_Link"/>
    <child link="RB_Link"/>
    <axis xyz="0 0 -1"/>
  </joint>
</robot>
